<?xml version="1.0" ?>
<!-- =================================================================================== -->
<!-- |    This document was autogenerated by xacro from irb1600_6_12.xacro             | -->
<!-- |    EDITING THIS FILE BY HAND IS NOT RECOMMENDED                                 | -->
<!-- =================================================================================== -->
<robot name="abb_irb1600_6_12" xmlns:xacro="http://ros.org/wiki/xacro">
  <link name="world"/>
  <link name="tsdf_frame"/>
  <!-- attach tsdf_frame to world -->
  <joint name="tsdf_to_world" type="fixed">
    <parent link="world"/>
    <child link="tsdf_frame"/>
    <origin rpy="0 0 0" xyz="0 0 0"/>
  </joint>
  <!-- link list -->
  <link name="base_link">
    <visual>
      <origin rpy="0 0 0" xyz="0 0 0"/>
      <geometry>
        <mesh filename="package://abb_irb1600_cal_support/meshes/irb1600/visual/base_link.stl"/>
      </geometry>
      <material name="abb_orange">
        <color rgba="1 0.43 0 1"/>
      </material>
    </visual>
    <collision>
      <geometry>
        <mesh filename="package://abb_irb1600_cal_support/meshes/irb1600/collision/base_link.stl"/>
      </geometry>
      <material name="yellow">
        <color rgba="0 1 1 1"/>
      </material>
    </collision>
  </link>
  <link name="link_1">
    <visual>
      <origin rpy="0 0 0" xyz="0 0 0"/>
      <geometry>
        <mesh filename="package://abb_irb1600_cal_support/meshes/irb1600/visual/link_1.stl"/>
      </geometry>
      <material name="abb_orange"/>
    </visual>
    <collision>
      <origin rpy="0 0 0" xyz="0 0 0"/>
      <geometry>
        <mesh filename="package://abb_irb1600_cal_support/meshes/irb1600/collision/link_1.stl"/>
      </geometry>
      <material name="yellow"/>
    </collision>
  </link>
  <link name="link_2">
    <visual>
      <origin rpy="0 0 0" xyz="0 0 0"/>
      <geometry>
        <mesh filename="package://abb_irb1600_cal_support/meshes/irb1600_6_12/visual/link_2.stl"/>
      </geometry>
      <material name="abb_orange"/>
    </visual>
    <collision>
      <origin rpy="0 0 0" xyz="0 0 0"/>
      <geometry>
        <mesh filename="package://abb_irb1600_cal_support/meshes/irb1600_6_12/collision/link_2.stl"/>
      </geometry>
      <material name="yellow"/>
    </collision>
  </link>
  <link name="link_3">
    <visual>
      <origin rpy="0 0 0" xyz="0 0 0"/>
      <geometry>
        <mesh filename="package://abb_irb1600_cal_support/meshes/irb1600/visual/link_3.stl"/>
      </geometry>
      <material name="abb_orange"/>
    </visual>
    <collision>
      <origin rpy="0 0 0" xyz="0 0 0"/>
      <geometry>
        <mesh filename="package://abb_irb1600_cal_support/meshes/irb1600/collision/link_3.stl"/>
      </geometry>
      <material name="yellow"/>
    </collision>
  </link>
  <link name="link_4">
    <visual>
      <origin rpy="0 0 0" xyz="0 0 0"/>
      <geometry>
        <mesh filename="package://abb_irb1600_cal_support/meshes/irb1600/visual/link_4.stl"/>
      </geometry>
      <material name="abb_orange"/>
    </visual>
    <collision>
      <origin rpy="0 0 0" xyz="0 0 0"/>
      <geometry>
        <mesh filename="package://abb_irb1600_cal_support/meshes/irb1600/collision/link_4.stl"/>
      </geometry>
      <material name="yellow"/>
    </collision>
  </link>
  <link name="link_5">
    <visual>
      <origin rpy="0 0 0" xyz="0 0 0"/>
      <geometry>
        <mesh filename="package://abb_irb1600_cal_support/meshes/irb1600/visual/link_5.stl"/>
      </geometry>
      <material name="abb_orange"/>
    </visual>
    <collision>
      <origin rpy="0 0 0" xyz="0 0 0"/>
      <geometry>
        <mesh filename="package://abb_irb1600_cal_support/meshes/irb1600/collision/link_5.stl"/>
      </geometry>
      <material name="yellow"/>
    </collision>
  </link>
  <link name="link_6">
    <visual>
      <origin rpy="0 0 0" xyz="0 0 0"/>
      <geometry>
        <mesh filename="package://abb_irb1600_cal_support/meshes/irb1600/visual/link_6.stl"/>
      </geometry>
      <material name="abb_orange"/>
    </visual>
    <collision>
      <origin rpy="0 0 0" xyz="0 0 0"/>
      <geometry>
        <mesh filename="package://abb_irb1600_cal_support/meshes/irb1600/collision/link_6.stl"/>
      </geometry>
      <material name="yellow"/>
    </collision>
  </link>
  <link name="tool0"/>
  <!-- end of link list -->
  <!-- joint list -->
  <joint name="joint_1" type="revolute">
    <origin rpy="0 0 0" xyz="0 0 0"/>
    <parent link="base_link"/>
    <child link="link_1"/>
    <axis xyz="0 0 1"/>
    <limit effort="0" lower="-3.14159265359" upper="3.14159265359" velocity="2.618"/>
  </joint>
  <joint name="joint_2" type="revolute">
    <origin rpy="0 0 0" xyz="0.15 0 0.4865"/>
    <parent link="link_1"/>
    <child link="link_2"/>
    <axis xyz="0 1 0"/>
    <limit effort="0" lower="-1.0995" upper="1.9198" velocity="2.7925"/>
  </joint>
  <joint name="joint_3" type="revolute">
    <origin rpy="0 0 0" xyz="0 0 0.475"/>
    <parent link="link_2"/>
    <child link="link_3"/>
    <axis xyz="0 1 0"/>
    <limit effort="0" lower="-4.1015" upper="0.9599" velocity="2.9670"/>
  </joint>
  <joint name="joint_4" type="revolute">
    <origin rpy="0 0 0" xyz="0.300 0 0"/>
    <parent link="link_3"/>
    <child link="link_4"/>
    <axis xyz="1 0 0"/>
    <limit effort="0" lower="-3.4906" upper="3.4906" velocity="5.5850"/>
  </joint>
  <joint name="joint_5" type="revolute">
    <origin rpy="0 0 0" xyz="0.300 0 0"/>
    <parent link="link_4"/>
    <child link="link_5"/>
    <axis xyz="0 1 0"/>
    <limit effort="0" lower="-2.0071" upper="2.0071" velocity="6.9813"/>
  </joint>
  <joint name="joint_6" type="revolute">
    <origin rpy="0 0 0" xyz="0.065 0 0"/>
    <parent link="link_5"/>
    <child link="link_6"/>
    <axis xyz="1 0 0"/>
    <limit effort="0" lower="-6.9813" upper="6.9813" velocity="7.854"/>
  </joint>
  <joint name="joint_6-tool0" type="fixed">
    <parent link="link_6"/>
    <child link="tool0"/>
    <origin rpy="0 1.57079632679 0" xyz="0 0 0"/>
  </joint>
  <!-- end of joint list -->
  <!-- attach robot to world -->
  <joint name="world_to_robot" type="fixed">
    <parent link="world"/>
    <child link="base_link"/>
    <origin rpy="0 0 0" xyz="0 0 0"/>
  </joint>
  <!-- add a target to the workcell -->
  <link name="target_frame"/>
  <link name="target_frame_x_trans">
    <visual>
      <origin rpy="0 0 0" xyz="0 0 0"/>
      <geometry>
        <sphere radius="0.0005"/>
      </geometry>
    </visual>
  </link>
  <link name="target_frame_y_trans"/>
  <link name="target_frame_z_trans"/>
  <link name="target_frame_pitch"/>
  <link name="target_frame_yaw"/>
  <joint name="target_frame_x_joint" type="prismatic">
    <parent link="world"/>
    <child link="target_frame_x_trans"/>
    <origin rpy="0 0 0" xyz="0 0 0"/>
    <axis rpy="0 0 0" xyz="1 0 0"/>
    <limit effort="30" lower="-1.0" upper="1.0" velocity="0.0508"/>
  </joint>
  <joint name="target_frame_y_joint" type="prismatic">
    <parent link="target_frame_x_trans"/>
    <child link="target_frame_y_trans"/>
    <origin rpy="0 0 0" xyz="0 0 0"/>
    <axis rpy="0 0 0" xyz="0 1 0"/>
    <limit effort="30" lower="-1.0" upper="1.0" velocity="0.0508"/>
  </joint>
  <joint name="target_frame_z_joint" type="prismatic">
    <parent link="target_frame_y_trans"/>
    <child link="target_frame_z_trans"/>
    <origin rpy="0 0 0" xyz="0 0 0"/>
    <axis rpy="0 0 0" xyz="0 0 1"/>
    <limit effort="30" lower="-1.0" upper="1.0" velocity="0.0508"/>
  </joint>
  <joint name="target_frame_yaw_joint" type="revolute">
    <parent link="target_frame_z_trans"/>
    <child link="target_frame_yaw"/>
    <origin rpy="0 0 0" xyz="0 0 0"/>
    <limit effort="2" lower="-6.2832" upper="6.2832" velocity="10"/>
    <axis xyz="0 0 1"/>
  </joint>
  <joint name="target_frame_pitch_joint" type="revolute">
    <parent link="target_frame_yaw"/>
    <child link="target_frame_pitch"/>
    <origin rpy="0 0 0" xyz="0 0 0"/>
    <limit effort="2" lower="-6.2832" upper="6.2832" velocity="10"/>
    <axis xyz="0 1 0"/>
  </joint>
  <joint name="target_frame_roll_joint" type="revolute">
    <parent link="target_frame_pitch"/>
    <child link="target_frame"/>
    <origin rpy="0 0 0" xyz="0 0 0"/>
    <limit effort="2" lower="-6.2832" upper="6.2832" velocity="10"/>
    <axis xyz="1 0 0"/>
  </joint>
  <!-- add a baser camera attached to the wrist -->
  <!--This adds the following mutable joint states, add them to the mutable joint states yaml file and run the node
      basler1_x_joint
      basler1_y_joint
      basler1_z_joint
      basler1_yaw_joint
      basler1_pitch_joint
      basler1_roll_joint    
      <xacro:basler_sensor_definitions prefix="basler1" parent_link="tool0"/>
  -->
  <material name="ifmdark_silver">
    <color rgba="0.30 0.30 0.30 1"/>
  </material>
  <!-- links: one for the optical frame and one for defining the link geometry -->
  <link name="ifm"/>
  <link name="ifm_optical_frame"/>
  <link name="o3d3xx/camera_optical_link"/>
  <link name="o3d3xx/camera_link"/>
  <link name="ifm_link">
    <visual>
      <origin rpy="0 0 0" xyz="0 0 -0.015"/>
      <geometry>
        <box size="0.07 0.07 0.08"/>
      </geometry>
      <material name="ifmdark_silver"/>
    </visual>
    <collision>
      <origin rpy="0 0 0" xyz="0 0 0"/>
      <geometry>
        <box size="0.07 0.08 0.07"/>
      </geometry>
    </collision>
  </link>
  <!-- end of sensor links -->
  <link name="ifm_x_trans">
    <visual>
      <origin rpy="0 0 0" xyz="0 0 0"/>
      <geometry>
        <sphere radius="0.0005"/>
      </geometry>
    </visual>
  </link>
  <link name="ifm_y_trans"/>
  <link name="ifm_z_trans"/>
  <link name="ifm_pitch"/>
  <link name="ifm_yaw"/>
  <joint name="ifm_x_joint" type="prismatic">
    <parent link="tool0"/>
    <child link="ifm_x_trans"/>
    <origin rpy="0 0 0" xyz="0 0 0"/>
    <axis rpy="0 0 0" xyz="1 0 0"/>
    <limit effort="30" lower="-1.0" upper="1.0" velocity="0.0508"/>
  </joint>
  <joint name="ifm_y_joint" type="prismatic">
    <parent link="ifm_x_trans"/>
    <child link="ifm_y_trans"/>
    <origin rpy="0 0 0" xyz="0 0 0"/>
    <axis rpy="0 0 0" xyz="0 1 0"/>
    <limit effort="30" lower="-1.0" upper="1.0" velocity="0.0508"/>
  </joint>
  <joint name="ifm_z_joint" type="prismatic">
    <parent link="ifm_y_trans"/>
    <child link="ifm_z_trans"/>
    <origin rpy="0 0 0" xyz="0 0 0"/>
    <axis rpy="0 0 0" xyz="0 0 1"/>
    <limit effort="30" lower="-1.0" upper="1.0" velocity="0.0508"/>
  </joint>
  <joint name="ifm_yaw_joint" type="revolute">
    <parent link="ifm_z_trans"/>
    <child link="ifm_yaw"/>
    <origin rpy="0 0 0" xyz="0 0 0"/>
    <limit effort="2" lower="-6.2832" upper="6.2832" velocity="10"/>
    <axis xyz="0 0 1"/>
  </joint>
  <joint name="ifm_pitch_joint" type="revolute">
    <parent link="ifm_yaw"/>
    <child link="ifm_pitch"/>
    <origin rpy="0 0 0" xyz="0 0 0"/>
    <limit effort="2" lower="-6.2832" upper="6.2832" velocity="10"/>
    <axis xyz="0 1 0"/>
  </joint>
  <joint name="ifm_roll_joint" type="revolute">
    <parent link="ifm_pitch"/>
    <child link="ifm"/>
    <origin rpy="0 0 0" xyz="0 0 0"/>
    <limit effort="2" lower="-6.2832" upper="6.2832" velocity="10"/>
    <axis xyz="1 0 0"/>
  </joint>
  <!-- joint to attach the optical frame -->
  <joint name="ifm_frame_joint" type="fixed">
    <parent link="ifm"/>
    <child link="ifm_optical_frame"/>
    <origin rpy="0 0 0" xyz="0 0 0"/>
  </joint>
  <!-- joint to attach the camera geometry to the optical frame -->
  <joint name="ifm_optical_joint" type="fixed">
    <parent link="ifm"/>
    <child link="ifm_link"/>
    <origin rpy="0 0 0" xyz="0 0 0"/>
  </joint>
  <joint name="ifm_sensor_joint" type="fixed">
    <parent link="ifm_link"/>
    <child link="o3d3xx/camera_link"/>
    <origin rpy="0 0.0 0" xyz="0 0 0"/>
  </joint>
  <joint name="ifm_sensor_joint2" type="fixed">
    <parent link="o3d3xx/camera_link"/>
    <child link="o3d3xx/camera_optical_link"/>
    <origin rpy="0 0 0" xyz="0 0 0"/>
  </joint>
  <!-- add an asus camera attached to the wrist -->
  <!--This adds the following mutable joint states, add them to the mutable joint states yaml file and run the node
      asus_link_x_joint
      asus_link_y_joint
      asus_link_z_joint
      asus_link_yaw_joint
      asus_link_pitch_joint
      asus_link_roll_joint
      <xacro:asus_sensor_definitions prefix="asus" parent_link="tool0"/>
      -->
  <material name="basler2dark_silver">
    <color rgba="0.30 0.30 0.30 1"/>
  </material>
  <!-- links: one for the optical frame and one for defining the link geometry -->
  <link name="basler2"/>
  <link name="basler2_optical_frame"/>
  <link name="basler2_link">
    <visual>
      <origin rpy="0 0 0" xyz="0 0 -0.015"/>
      <geometry>
        <box size="0.03 0.03 0.1"/>
      </geometry>
      <material name="basler2dark_silver"/>
    </visual>
    <collision>
      <origin rpy="0 0 0" xyz="0 0 0"/>
      <geometry>
        <box size="0.03 0.1 0.03"/>
      </geometry>
    </collision>
  </link>
  <!-- end of sensor links -->
  <link name="basler2_x_trans">
    <visual>
      <origin rpy="0 0 0" xyz="0 0 0"/>
      <geometry>
        <sphere radius="0.0005"/>
      </geometry>
    </visual>
  </link>
  <link name="basler2_y_trans"/>
  <link name="basler2_z_trans"/>
  <link name="basler2_pitch"/>
  <link name="basler2_yaw"/>
  <joint name="basler2_x_joint" type="prismatic">
    <parent link="world"/>
    <child link="basler2_x_trans"/>
    <origin rpy="0 0 0" xyz="0 0 0"/>
    <axis rpy="0 0 0" xyz="1 0 0"/>
    <limit effort="30" lower="-1.0" upper="1.0" velocity="0.0508"/>
  </joint>
  <joint name="basler2_y_joint" type="prismatic">
    <parent link="basler2_x_trans"/>
    <child link="basler2_y_trans"/>
    <origin rpy="0 0 0" xyz="0 0 0"/>
    <axis rpy="0 0 0" xyz="0 1 0"/>
    <limit effort="30" lower="-1.0" upper="1.0" velocity="0.0508"/>
  </joint>
  <joint name="basler2_z_joint" type="prismatic">
    <parent link="basler2_y_trans"/>
    <child link="basler2_z_trans"/>
    <origin rpy="0 0 0" xyz="0 0 0"/>
    <axis rpy="0 0 0" xyz="0 0 1"/>
    <limit effort="30" lower="-1.0" upper="1.0" velocity="0.0508"/>
  </joint>
  <joint name="basler2_yaw_joint" type="revolute">
    <parent link="basler2_z_trans"/>
    <child link="basler2_yaw"/>
    <origin rpy="0 0 0" xyz="0 0 0"/>
    <limit effort="2" lower="-6.2832" upper="6.2832" velocity="10"/>
    <axis xyz="0 0 1"/>
  </joint>
  <joint name="basler2_pitch_joint" type="revolute">
    <parent link="basler2_yaw"/>
    <child link="basler2_pitch"/>
    <origin rpy="0 0 0" xyz="0 0 0"/>
    <limit effort="2" lower="-6.2832" upper="6.2832" velocity="10"/>
    <axis xyz="0 1 0"/>
  </joint>
  <joint name="basler2_roll_joint" type="revolute">
    <parent link="basler2_pitch"/>
    <child link="basler2"/>
    <origin rpy="0 0 0" xyz="0 0 0"/>
    <limit effort="2" lower="-6.2832" upper="6.2832" velocity="10"/>
    <axis xyz="1 0 0"/>
  </joint>
  <!-- joint to attach the optical frame -->
  <joint name="basler2_frame_joint" type="fixed">
    <parent link="basler2"/>
    <child link="basler2_optical_frame"/>
    <origin rpy="0 0 0" xyz="0 0 0"/>
  </joint>
  <!-- joint to attach the camera geometry to the optical frame -->
  <joint name="basler2_optical_joint" type="fixed">
    <parent link="basler2"/>
    <child link="basler2_link"/>
    <origin rpy="0 0 0" xyz="0 0 0"/>
  </joint>
</robot>

